Workbook

Sheet Indice
A1: Diccionario de datos | Plataforma Integrada de Calidad (P.I.C.)
A2: TT2 2026-B060 | HIMFG | PostgreSQL 14+ | Versión 1.0 | 13/10/2026
A4: # | B4: Tabla | C4: Zona | D4: Hoja | E4: Descripción | F4: Columnas | G4: FK salientes
A5: 1 | B5: rol | C5: Seguridad y usuarios | D5: Seguridad | E5: Roles del sistema (RBAC). | F5: =COUNTIF(Seguridad!$A:$A,B5) -> 6 | G5: =COUNTIF(Relaciones!$A$4:$A$89,B5) -> 0
A6: 2 | B6: permiso | C6: Seguridad y usuarios | D6: Seguridad | E6: Permisos granulares por módulo y acción. | F6: =COUNTIF(Seguridad!$A:$A,B6) -> 6 | G6: =COUNTIF(Relaciones!$A$4:$A$89,B6) -> 0
A7: 3 | B7: rol_permiso | C7: Seguridad y usuarios | D7: Seguridad | E7: Asignación de permisos a roles. | F7: =COUNTIF(Seguridad!$A:$A,B7) -> 2 | G7: =COUNTIF(Relaciones!$A$4:$A$89,B7) -> 2
A8: 4 | B8: usuario | C8: Seguridad y usuarios | D8: Seguridad | E8: Cuentas de usuarios internos (RF-001, RF-002, CU-07, CU-08). | F8: =COUNTIF(Seguridad!$A:$A,B8) -> 16 | G8: =COUNTIF(Relaciones!$A$4:$A$89,B8) -> 2
A9: 5 | B9: catalogo | C9: Catálogos y datos maestros | D9: Catalogos | E9: Definición de catálogos parametrizables (RF-003, DEC-11). | F9: =COUNTIF(Catalogos!$A:$A,B9) -> 7 | G9: =COUNTIF(Relaciones!$A$4:$A$89,B9) -> 0
A10: 6 | B10: catalogo_item | C10: Catálogos y datos maestros | D10: Catalogos | E10: Elementos de catálogo; jerarquía mediante padre_id. | F10: =COUNTIF(Catalogos!$A:$A,B10) -> 10 | G10: =COUNTIF(Relaciones!$A$4:$A$89,B10) -> 2
A11: 7 | B11: servicio | C11: Catálogos y datos maestros | D11: Catalogos | E11: Unidades organizacionales: áreas de atención y servicios relacionados. | F11: =COUNTIF(Catalogos!$A:$A,B11) -> 7 | G11: =COUNTIF(Relaciones!$A$4:$A$89,B11) -> 0
A12: 8 | B12: diagnostico | C12: Catálogos y datos maestros | D12: Catalogos | E12: Catálogo de diagnósticos (aprox. 14,000 registros). | F12: =COUNTIF(Catalogos!$A:$A,B12) -> 6 | G12: =COUNTIF(Relaciones!$A$4:$A$89,B12) -> 0
A13: 9 | B13: paciente | C13: Catálogos y datos maestros | D13: Catalogos | E13: Identificación mínima del paciente (dato personal sensible, RNF-006). | F13: =COUNTIF(Catalogos!$A:$A,B13) -> 9 | G13: =COUNTIF(Relaciones!$A$4:$A$89,B13) -> 1
A14: 10 | B14: establecimiento | C14: Catálogos y datos maestros | D14: Catalogos | E14: Datos del establecimiento precargados en SESTAD (RF-028). | F14: =COUNTIF(Catalogos!$A:$A,B14) -> 8 | G14: =COUNTIF(Relaciones!$A$4:$A$89,B14) -> 0
A15: 11 | B15: bitacora | C15: Servicios transversales | D15: Transversales | E15: Bitácora de auditoría de solo inserción (RF-007, CU-10, DEC-04). | F15: =COUNTIF(Transversales!$A:$A,B15) -> 11 | G15: =COUNTIF(Relaciones!$A$4:$A$89,B15) -> 1
A16: 12 | B16: notificacion | C16: Servicios transversales | D16: Transversales | E16: Notificaciones internas, una fila por destinatario (RF-008). | F16: =COUNTIF(Transversales!$A:$A,B16) -> 10 | G16: =COUNTIF(Relaciones!$A$4:$A$89,B16) -> 1
A17: 13 | B17: archivo_adjunto | C17: Servicios transversales | D17: Transversales | E17: Metadatos de archivos en disco; relación polimórfica (DEC-13). | F17: =COUNTIF(Transversales!$A:$A,B17) -> 11 | G17: =COUNTIF(Relaciones!$A$4:$A$89,B17) -> 1
A18: 14 | B18: borrador | C18: Servicios transversales | D18: Transversales | E18: Borradores de formularios con autoguardado (RNF-012, DEC-07). | F18: =COUNTIF(Transversales!$A:$A,B18) -> 7 | G18: =COUNTIF(Relaciones!$A$4:$A$89,B18) -> 1
A19: 15 | B19: folio_secuencia | C19: Servicios transversales | D19: Transversales | E19: Consecutivos de folio por módulo y año (DEC-08). | F19: =COUNTIF(Transversales!$A:$A,B19) -> 3 | G19: =COUNTIF(Relaciones!$A$4:$A$89,B19) -> 0
A20: 16 | B20: modulo_sistema | C20: Servicios transversales | D20: Transversales | E20: Módulos y su habilitación (MECIC e INDICAS II en falso, DEC-15). | F20: =COUNTIF(Transversales!$A:$A,B20) -> 6 | G20: =COUNTIF(Relaciones!$A$4:$A$89,B20) -> 0
A21: 17 | B21: reporte_generado | C21: Servicios transversales | D21: Transversales | E21: Historial de reportes y exportaciones DGCES (CU-12). | F21: =COUNTIF(Transversales!$A:$A,B21) -> 9 | G21: =COUNTIF(Relaciones!$A$4:$A$89,B21) -> 2
A22: 18 | B22: oficio | C22: Servicios transversales | D22: Transversales | E22: Oficios de solicitud y respuesta, compartidos por SREA y SUG (DEC-09). | F22: =COUNTIF(Transversales!$A:$A,B22) -> 13 | G22: =COUNTIF(Relaciones!$A$4:$A$89,B22) -> 4
A23: 19 | B23: incidente | C23: SREA: Notificación de incidentes | D23: SREA | E23: Notificación de IRSP, formato MP-6001-213-03 (CU-01, CU-02). | F23: =COUNTIF(SREA!$A:$A,B23) -> 32 | G23: =COUNTIF(Relaciones!$A$4:$A$89,B23) -> 11
A24: 20 | B24: incidente_tipo | C24: SREA: Notificación de incidentes | D24: SREA | E24: Tipo y subtipo de incidente (RF-010); orden 1 y 2 como en la base IRSP. | F24: =COUNTIF(SREA!$A:$A,B24) -> 4 | G24: =COUNTIF(Relaciones!$A$4:$A$89,B24) -> 2
A25: 21 | B25: incidente_dano | C25: SREA: Notificación de incidentes | D25: SREA | E25: Daño atribuido al incidente (RF-011). | F25: =COUNTIF(SREA!$A:$A,B25) -> 3 | G25: =COUNTIF(Relaciones!$A$4:$A$89,B25) -> 2
A26: 22 | B26: incidente_factor | C26: SREA: Notificación de incidentes | D26: SREA | E26: Factores contribuyentes (RF-011). | F26: =COUNTIF(SREA!$A:$A,B26) -> 3 | G26: =COUNTIF(Relaciones!$A$4:$A$89,B26) -> 2
A27: 23 | B27: incidente_personal | C27: SREA: Notificación de incidentes | D27: SREA | E27: Perfil del personal involucrado (RF-014). | F27: =COUNTIF(SREA!$A:$A,B27) -> 3 | G27: =COUNTIF(Relaciones!$A$4:$A$89,B27) -> 2
A28: 24 | B28: incidente_servicio_rel | C28: SREA: Notificación de incidentes | D28: SREA | E28: Servicios relacionados con el incidente. | F28: =COUNTIF(SREA!$A:$A,B28) -> 2 | G28: =COUNTIF(Relaciones!$A$4:$A$89,B28) -> 2
A29: 25 | B29: medicamento_insumo | C29: SREA: Notificación de incidentes | D29: SREA | E29: Medicamento o dispositivo involucrado (RF-012, CU-01 A1). | F29: =COUNTIF(SREA!$A:$A,B29) -> 9 | G29: =COUNTIF(Relaciones!$A$4:$A$89,B29) -> 1
A30: 26 | B30: accion_reduccion_riesgo | C30: SREA: Notificación de incidentes | D30: SREA | E30: Acciones de reducción de riesgos (RF-013). | F30: =COUNTIF(SREA!$A:$A,B30) -> 6 | G30: =COUNTIF(Relaciones!$A$4:$A$89,B30) -> 1
A31: 27 | B31: analisis_causa_raiz | C31: SREA: Notificación de incidentes | D31: SREA | E31: Análisis causa-efecto, formato MP-1021-237-05 (RF-018, CU-02 A1). | F31: =COUNTIF(SREA!$A:$A,B31) -> 10 | G31: =COUNTIF(Relaciones!$A$4:$A$89,B31) -> 3
A32: 28 | B32: acr_cronologia | C32: SREA: Notificación de incidentes | D32: SREA | E32: Cronología narrativa del ACR. | F32: =COUNTIF(SREA!$A:$A,B32) -> 8 | G32: =COUNTIF(Relaciones!$A$4:$A$89,B32) -> 1
A33: 29 | B33: acr_causa | C33: SREA: Notificación de incidentes | D33: SREA | E33: Causas del diagrama de Ishikawa. | F33: =COUNTIF(SREA!$A:$A,B33) -> 7 | G33: =COUNTIF(Relaciones!$A$4:$A$89,B33) -> 1
A34: 30 | B34: accion_mejora | C34: SREA: Notificación de incidentes | D34: SREA | E34: Acciones de mejora con responsable y fecha (RF-019, CU-13). | F34: =COUNTIF(SREA!$A:$A,B34) -> 12 | G34: =COUNTIF(Relaciones!$A$4:$A$89,B34) -> 4
... A36: 32 | B36: evidencia | C36: SREA: Notificación de incidentes | D36: SREA | E36: Evidencia de cumplimiento; archivos en archivo_adjunto (CU-14). | F36: =COUNTIF(SREA!$A:$A,B36) -> 11 | G36: =COUNTIF(Relaciones!$A$4:$A$89,B36) -> 3
A37: 33 | B37: instrumento | C37: Motor de encuestas (SUG y SESTAD) | D37: Motor_encuestas | E37: Formato de encuesta versionado (egreso, SESTAD CE, HOSP, URG). | F37: =COUNTIF(Motor_encuestas!$A:$A,B37) -> 9 | G37: =COUNTIF(Relaciones!$A$4:$A$89,B37) -> 0
A38: 34 | B38: instrumento_seccion | C38: Motor de encuestas (SUG y SESTAD) | D38: Motor_encuestas | E38: Secciones del instrumento. | F38: =COUNTIF(Motor_encuestas!$A:$A,B38) -> 7 | G38: =COUNTIF(Relaciones!$A$4:$A$89,B38) -> 1
A39: 35 | B39: pregunta | C39: Motor de encuestas (SUG y SESTAD) | D39: Motor_encuestas | E39: Reactivos con lógica de salto. | F39: =COUNTIF(Motor_encuestas!$A:$A,B39) -> 11 | G39: =COUNTIF(Relaciones!$A$4:$A$89,B39) -> 3
A40: 36 | B40: opcion_respuesta | C40: Motor de encuestas (SUG y SESTAD) | D40: Motor_encuestas | E40: Opciones de respuesta por pregunta. | F40: =COUNTIF(Motor_encuestas!$A:$A,B40) -> 9 | G40: =COUNTIF(Relaciones!$A$4:$A$89,B40) -> 1
A41: 37 | B41: encuesta | C41: Motor de encuestas (SUG y SESTAD) | D41: Motor_encuestas | E41: Encuesta aplicada (CU-03, CU-17). | F41: =COUNTIF(Motor_encuestas!$A:$A,B41) -> 11 | G41: =COUNTIF(Relaciones!$A$4:$A$89,B41) -> 2
A42: 38 | B42: respuesta | C42: Motor de encuestas (SUG y SESTAD) | D42: Motor_encuestas | E42: Respuestas normalizadas; base del concentrado (RF-030). | F42: =COUNTIF(Motor_encuestas!$A:$A,B42) -> 6 | G42: =COUNTIF(Relaciones!$A$4:$A$89,B42) -> 3
...

Sheet Seguridad
A1: Diccionario de datos | Seguridad y usuarios
A2: P.I.C. TT2 2026-B060 | PostgreSQL 14+ | Fuente: modelo_er_tt2.drawio
A4: Tabla | B4: # | C4: Columna | D4: Tipo PostgreSQL | E4: PK | F4: FK | G4: Único | H4: Nulo | I4: Referencia | J4: Descripción
A5: rol | Roles del sistema (RBAC).
A6: rol | B6: 1 | C6: id | D6: SMALLINT | E6: Sí | H6: No | J6: Identificador del rol.
A7: rol | B7: 2 | C7: clave | D7: VARCHAR(30) | G7: Sí | H7: No | J7: ADMIN, CALIDAD, SALUD, EVALUADOR_MECIC, PACIENTE, SISTEMA.
A8: rol | B8: 3 | C8: nombre | D8: VARCHAR(80) | H8: No | J8: Nombre visible del rol.
A9: rol | B9: 4 | C9: descripcion | D9: VARCHAR(255) | H9: Sí | J9: Descripción del rol.
A10: rol | B10: 5 | C10: created_at | D10: TIMESTAMPTZ | H10: No | J10: Fecha de creación (Sequelize).
A11: rol | B11: 6 | C11: updated_at | D11: TIMESTAMPTZ | H11: No | J11: Fecha de última modificación (Sequelize).
A13: permiso | Permisos granulares por módulo y acción.
A14: permiso | B14: 1 | C14: id | D14: INTEGER | E14: Sí | H14: No | J14: Identificador del permiso.
A15: permiso | B15: 2 | C15: clave | D15: VARCHAR(80) | G15: Sí | H15: No | J15: Clave modulo.recurso.accion, ej. srea.incidente.clasificar.
A16: permiso | B16: 3 | C16: modulo | D16: VARCHAR(30) | H16: No | J16: Módulo al que pertenece el permiso.
A17: permiso | B17: 4 | C17: descripcion | D17: VARCHAR(255) | H17: Sí | J17: Descripción del permiso.
A18: permiso | B18: 5 | C18: created_at | D18: TIMESTAMPTZ | H18: No | J18: Fecha de creación (Sequelize).
A19: permiso | B19: 6 | C19: updated_at | D19: TIMESTAMPTZ | H19: No | J19: Fecha de última modificación (Sequelize).
A21: rol_permiso | Asignación de permisos a roles.
A22: rol_permiso | B22: 1 | C22: rol_id | D22: SMALLINT | E22: Sí | F22: Sí | H22: No | I22: rol.id | J22: Rol.
A23: rol_permiso | B23: 2 | C23: permiso_id | D23: INTEGER | E23: Sí | F23: Sí | H23: No | I23: permiso.id | J23: Permiso otorgado.
A25: usuario | Cuentas de usuarios internos (RF-001, RF-002, CU-07, CU-08).
A26: usuario | B26: 1 | C26: id | D26: INTEGER | E26: Sí | H26: No | J26: Identificador del usuario.
A27: usuario | B27: 2 | C27: nombre | D27: VARCHAR(80) | H27: No | J27: Nombre(s).
A28: usuario | B28: 3 | C28: apellido_paterno | D28: VARCHAR(80) | H28: No | J28: Apellido paterno.
A29: usuario | B29: 4 | C29: apellido_materno | D29: VARCHAR(80) | H29: Sí | J29: Apellido materno.
A30: usuario | B30: 5 | C30: correo | D30: VARCHAR(120) | G30: Sí | H30: No | J30: Correo institucional; usado como nombre de usuario.
A31: usuario | B31: 6 | C31: password_hash | D31: VARCHAR(100) | H31: No | J31: Hash bcrypt (RNF-002).
A32: usuario | B32: 7 | C32: rol_id | D32: SMALLINT | F32: Sí | H32: No | I32: rol.id | J32: Rol asignado (un rol por usuario).
A33: usuario | B33: 8 | C33: servicio_id | D33: INTEGER | F33: Sí | H33: Sí | I33: servicio.id | J33: Área de adscripción; filtra acciones de mejora (CU-14).
A34: usuario | B34: 9 | C34: activo | D34: BOOLEAN | H34: No | J34: Desactivación lógica (CU-08 A2).
A35: usuario | B35: 10 | C35: intentos_fallidos | D35: SMALLINT | H35: No | J35: Intentos fallidos consecutivos (CU-07 A3).
A36: usuario | B36: 11 | C36: bloqueado_hasta | D36: TIMESTAMPTZ | H36: Sí | J36: Fin del bloqueo temporal de 15 min.
A37: usuario | B37: 12 | C37: debe_cambiar_password | D37: BOOLEAN | H37: No | J37: Obliga cambio en el primer ingreso (CU-08 A1).
A38: usuario | B38: 13 | C38: token_version | D38: INTEGER | H38: No | J38: Se incrementa para invalidar sesiones activas (CU-08 A4).
A39: usuario | B39: 14 | C39: ultimo_acceso | D39: TIMESTAMPTZ | H39: Sí | J39: Fecha del último inicio de sesión.
A40: usuario | B40: 15 | C40: created_at | D40: TIMESTAMPTZ | H40: No | J40: Fecha de creación (Sequelize).
A41: usuario | B41: 16 | C41: updated_at | D41: TIMESTAMPTZ | H41: No | J41: Fecha de última modificación (Sequelize).

Sheet Catalogos
A1: Diccionario de datos | Catálogos y datos maestros
A2: P.I.C. TT2 2026-B060 | PostgreSQL 14+ | Fuente: modelo_er_tt2.drawio
A4: Tabla | B4: # | C4: Columna | D4: Tipo PostgreSQL | E4: PK | F4: FK | G4: Único | H4: Nulo | I4: Referencia | J4: Descripción
A5: catalogo | Definición de catálogos parametrizables (RF-003, DEC-11).
A6: catalogo | B6: 1 | C6: id | D6: INTEGER | E6: Sí | H6: No | J6: Identificador del catálogo.
A7: catalogo | B7: 2 | C7: clave | D7: VARCHAR(50) | G7: Sí | H7: No | J7: Ej. TIPO_INCIDENTE, TURNO, DANO_PACIENTE.
A8: catalogo | B8: 3 | C8: nombre | D8: VARCHAR(120) | H8: No | J8: Nombre visible.
A9: catalogo | B9: 4 | C9: jerarquico | D9: BOOLEAN | H9: No | J9: Indica si los elementos admiten padre.
A10: catalogo | B10: 5 | C10: editable | D10: BOOLEAN | H10: No | J10: Si el Administrador puede modificarlo.
A11: catalogo | B11: 6 | C11: created_at | D11: TIMESTAMPTZ | H11: No | J11: Fecha de creación (Sequelize).
A12: catalogo | B12: 7 | C12: updated_at | D12: TIMESTAMPTZ | H12: No | J12: Fecha de última modificación (Sequelize).
A14: catalogo_item | Elementos de catálogo; jerarquía mediante padre_id.
A15: catalogo_item | B15: 1 | C15: id | D15: INTEGER | E15: Sí | H15: No | J15: Identificador del elemento.
A16: catalogo_item | B16: 2 | C16: catalogo_id | D16: INTEGER | F16: Sí | G16: Comp. | H16: No | I16: catalogo.id | J16: Catálogo al que pertenece.
A17: catalogo_item | B17: 3 | C17: padre_id | D17: INTEGER | F17: Sí | G17: Comp. | H17: Sí | I17: catalogo_item.id | J17: Elemento padre (ej. tipo de incidente de un subtipo).
A18: catalogo_item | B18: 4 | C18: clave | D18: VARCHAR(50) | H18: Sí | J18: Clave técnica opcional.
A19: catalogo_item | B19: 5 | C19: nombre | D19: VARCHAR(255) | G19: Comp. | H19: No | J19: Texto visible.
A20: catalogo_item | B20: 6 | C20: orden | D20: SMALLINT | H20: Sí | J20: Orden de presentación.
A21: catalogo_item | B21: 7 | C21: requiere_especificar | D21: BOOLEAN | H21: No | J21: Habilita campo 'Otros, especifique'.
A22: catalogo_item | B22: 8 | C22: activo | D22: BOOLEAN | H22: No | J22: Desactivación lógica (CU-09 A1).
A23: catalogo_item | B23: 9 | C23: created_at | D23: TIMESTAMPTZ | H23: No | J23: Fecha de creación (Sequelize).
A24: catalogo_item | B24: 10 | C24: updated_at | D24: TIMESTAMPTZ | H24: No | J24: Fecha de última modificación (Sequelize).
A26: servicio | Unidades organizacionales: áreas de atención y servicios relacionados.
A27: servicio | B27: 1 | C27: id | D27: INTEGER | E27: Sí | H27: No | J27: Identificador del servicio.
A28: servicio | B28: 2 | C28: clave | D28: VARCHAR(30) | G28: Sí | H28: Sí | J28: Clave interna.
A29: servicio | B29: 3 | C29: nombre | D29: VARCHAR(160) | G29: Sí | H29: No | J29: Nombre oficial del servicio o departamento.
A30: servicio | B30: 4 | C30: es_area_atencion | D30: BOOLEAN | H30: No | J30: True si puede ser lugar de ocurrencia de un incidente.
A31: servicio | B31: 5 | C31: activo | D31: BOOLEAN | H31: No | J31: Desactivación lógica.
A32: servicio | B32: 6 | C32: created_at | D32: TIMESTAMPTZ | H32: No | J32: Fecha de creación (Sequelize).
A33: servicio | B33: 7 | C33: updated_at | D33: TIMESTAMPTZ | H33: No | J33: Fecha de última modificación (Sequelize).
A35: diagnostico | Catálogo de diagnósticos (aprox. 14,000 registros).
A36: diagnostico | B36: 1 | C36: id | D36: INTEGER | E36: Sí | H36: No | J36: Identificador.
A37: diagnostico | B37: 2 | C37: codigo_cie10 | D37: VARCHAR(10) | H37: Sí | J37: Código CIE-10; pendiente, la fuente no lo incluye.
A38: diagnostico | B38: 3 | C38: descripcion | D38: VARCHAR(255) | H38: No | J38: Descripción; índice pg_trgm para autocompletado.
A39: diagnostico | B39: 4 | C39: activo | D39: BOOLEAN | H39: No | J39: Desactivación lógica.
A40: diagnostico | B40: 5 | C40: created_at | D40: TIMESTAMPTZ | H40: No | J40: Fecha de creación (Sequelize).
A41: diagnostico | B41: 6 | C41: updated_at | D41: TIMESTAMPTZ | H41: No | J41: Fecha de última modificación (Sequelize).
A43: paciente | Identificación mínima del paciente (dato personal sensible, RNF-006).
A44: paciente | B44: 1 | C44: id | D44: INTEGER | E44: Sí | H44: No | J44: Identificador.
A45: paciente | B45: 2 | C45: numero_registro | D45: VARCHAR(20) | G45: Sí | H45: No | J45: Número de expediente del HIMFG.
...

Sheet Transversales
A1: Diccionario de datos | Servicios transversales
A2: P.I.C. TT2 2026-B060 | PostgreSQL 14+ | Fuente: modelo_er_tt2.drawio
A4: Tabla | B4: # | C4: Columna | D4: Tipo PostgreSQL | E4: PK | F4: FK | G4: Único | H4: Nulo | I4: Referencia | J4: Descripción
A5: bitacora | Bitácora de auditoría de solo inserción (RF-007, CU-10, DEC-04).
A6: bitacora | B6: 1 | C6: id | D6: BIGINT | E6: Sí | H6: No | J6: Identificador.
A7: bitacora | B7: 2 | C7: fecha | D7: TIMESTAMPTZ | H7: No | J7: Momento del evento.
A8: bitacora | B8: 3 | C8: usuario_id | D8: INTEGER | F8: Sí | H8: Sí | I8: usuario.id | J8: Actor; nulo para acciones del actor Sistema o públicas.
A9: bitacora | B9: 4 | C9: accion | D9: VARCHAR(30) | H9: No | J9: CREAR, ACTUALIZAR, ELIMINAR, LOGIN, LOGIN_FALLIDO, BLOQUEO, EXPORTAR, CONSULTAR.
A10: bitacora | B10: 5 | C10: modulo | D10: VARCHAR(30) | H10: No | J10: Módulo de origen.
A11: bitacora | B11: 6 | C11: entidad | D11: VARCHAR(50) | H11: Sí | J11: Tabla afectada.
A12: bitacora | B12: 7 | C12: entidad_id | D12: BIGINT | H12: Sí | J12: Registro afectado.
A13: bitacora | B13: 8 | C13: datos_antes | D13: JSONB | H13: Sí | J13: Estado previo.
A14: bitacora | B14: 9 | C14: datos_despues | D14: JSONB | H14: Sí | J14: Estado posterior.
A15: bitacora | B15: 10 | C15: ip | D15: INET | H15: Sí | J15: Dirección IP de origen.
A16: bitacora | B16: 11 | C16: user_agent | D16: VARCHAR(255) | H16: Sí | J16: Agente de usuario.
A18: notificacion | Notificaciones internas, una fila por destinatario (RF-008).
A19: notificacion | B19: 1 | C19: id | D19: BIGINT | E19: Sí | H19: No | J19: Identificador.
A20: notificacion | B20: 2 | C20: usuario_id | D20: INTEGER | F20: Sí | H20: No | I20: usuario.id | J20: Destinatario.
A21: notificacion | B21: 3 | C21: tipo | D21: VARCHAR(40) | H21: No | J21: Ej. NUEVO_INCIDENTE, QSF_PENDIENTE, EVIDENCIA_ENTREGADA.
A22: notificacion | B22: 4 | C22: titulo | D22: VARCHAR(160) | H22: No | J22: Título.
A23: notificacion | B23: 5 | C23: mensaje | D23: TEXT | H23: Sí | J23: Cuerpo.
A24: notificacion | B24: 6 | C24: entidad | D24: VARCHAR(50) | H24: Sí | J24: Entidad relacionada para navegación.
A25: notificacion | B25: 7 | C25: entidad_id | D25: BIGINT | H25: Sí | J25: Registro relacionado.
A26: notificacion | B26: 8 | C26: leida_en | D26: TIMESTAMPTZ | H26: Sí | J26: Nulo mientras no se lee.
A27: notificacion | B27: 9 | C27: created_at | D27: TIMESTAMPTZ | H27: No | J27: Fecha de creación (Sequelize).
A28: notificacion | B28: 10 | C28: updated_at | D28: TIMESTAMPTZ | H28: No | J28: Fecha de última modificación (Sequelize).
A30: archivo_adjunto | Metadatos de archivos en disco; relación polimórfica (DEC-13).
A31: archivo_adjunto | B31: 1 | C31: id | D31: BIGINT | E31: Sí | H31: No | J31: Identificador.
A32: archivo_adjunto | B32: 2 | C32: nombre_original | D32: VARCHAR(255) | H32: No | J32: Nombre del archivo cargado.
A33: archivo_adjunto | B33: 3 | C33: nombre_almacenado | D33: VARCHAR(100) | G33: Sí | H33: No | J33: Nombre aleatorio en disco.
A34: archivo_adjunto | B34: 4 | C34: mime_type | D34: VARCHAR(100) | H34: No | J34: Tipo verificado por firma.
A35: archivo_adjunto | B35: 5 | C35: tamano_bytes | D35: INTEGER | H35: No | J35: Máximo 10 MB.
A36: archivo_adjunto | B36: 6 | C36: hash_sha256 | D36: CHAR(64) | H36: No | J36: Integridad del archivo.
A37: archivo_adjunto | B37: 7 | C37: entidad | D37: VARCHAR(50) | H37: No | J37: CHECK: incidente, evidencia, oficio, reporte_generado, qsf.
A38: archivo_adjunto | B38: 8 | C38: entidad_id | D38: BIGINT | H38: No | J38: Registro propietario.
A39: archivo_adjunto | B39: 9 | C39: subido_por | D39: INTEGER | F39: Sí | H39: Sí | I39: usuario.id | J39: Usuario que cargó el archivo.
A40: archivo_adjunto | B40: 10 | C40: created_at | D40: TIMESTAMPTZ | H40: No | J40: Fecha de creación (Sequelize).
A41: archivo_adjunto | B41: 11 | C41: updated_at | D41: TIMESTAMPTZ | H41: No | J41: Fecha de última modificación (Sequelize).
A43: borrador | Borradores de formularios con autoguardado (RNF-012, DEC-07).
A44: borrador | B44: 1 | C44: id | D44: BIGINT | E44: Sí | H44: No | J44: Identificador.
...

Sheet SREA
A1: Diccionario de datos | SREA: Notificación de incidentes
A2: P.I.C. TT2 2026-B060 | PostgreSQL 14+ | Fuente: modelo_er_tt2.drawio
A4: Tabla | B4: # | C4: Columna | D4: Tipo PostgreSQL | E4: PK | F4: FK | G4: Único | H4: Nulo | I4: Referencia | J4: Descripción
A5: incidente | Notificación de IRSP, formato MP-6001-213-03 (CU-01, CU-02).
A6: incidente | B6: 1 | C6: id | D6: INTEGER | E6: Sí | H6: No | J6: Identificador.
A7: incidente | B7: 2 | C7: folio | D7: VARCHAR(20) | G7: Sí | H7: No | J7: SREA-AAAA-NNNN (RF-016).
A8: incidente | B8: 3 | C8: estatus | D8: VARCHAR(30) | H8: No | J8: PENDIENTE_CLASIFICACION, REQUIERE_INFORMACION, CLASIFICADO, EN_ANALISIS, PENDIENTE_EVIDENCIA, CERRADO.
A9: incidente | B9: 4 | C9: origen | D9: VARCHAR(10) | H9: No | J9: DIRECTO, QSF.
A10: incidente | B10: 5 | C10: qsf_id | D10: INTEGER | F10: Sí | G10: Sí | H10: Sí | I10: qsf.id | J10: QSF de la que deriva (RF-026).
A11: incidente | B11: 6 | C11: notificante_id | D11: INTEGER | F11: Sí | H11: No | I11: usuario.id | J11: Usuario que notifica.
A12: incidente | B12: 7 | C12: fecha_incidente | D12: DATE | H12: No | J12: Fecha de ocurrencia.
A13: incidente | B13: 8 | C13: hora_incidente | D13: TIME | H13: Sí | J13: Hora de ocurrencia.
A14: incidente | B14: 9 | C14: fecha_notificacion | D14: TIMESTAMPTZ | H14: No | J14: Momento del registro.
A15: incidente | B15: 10 | C15: servicio_ocurrencia_id | D15: INTEGER | F15: Sí | H15: No | I15: servicio.id | J15: Servicio donde ocurrió.
A16: incidente | B16: 11 | C16: turno_id | D16: INTEGER | F16: Sí | H16: Sí | I16: catalogo_item.id | J16: Catálogo TURNO.
A17: incidente | B17: 12 | C17: paciente_id | D17: INTEGER | F17: Sí | H17: Sí | I17: paciente.id | J17: Nulo en factores contribuyentes sin paciente.
A18: incidente | B18: 13 | C18: peso_kg | D18: NUMERIC(5,2) | H18: Sí | J18: Peso al momento del incidente.
A19: incidente | B19: 14 | C19: talla_m | D19: NUMERIC(4,2) | H19: Sí | J19: Talla al momento del incidente.
A20: incidente | B20: 15 | C20: diagnostico_id | D20: INTEGER | F20: Sí | H20: Sí | I20: diagnostico.id | J20: Diagnóstico actual.
A21: incidente | B21: 16 | C21: descripcion | D21: TEXT | H21: No | J21: Narración cronológica de los hechos.
A22: incidente | B22: 17 | C22: descripcion_dano | D22: TEXT | H22: Sí | J22: Descripción del daño o consecuencias.
A23: incidente | B23: 18 | C23: otro_personal | D23: VARCHAR(255) | H23: Sí | J23: Personal involucrado no catalogado.
A24: incidente | B24: 19 | C24: recibido_por | D24: INTEGER | F24: Sí | H24: Sí | I24: usuario.id | J24: Personal de Calidad que recibe.
A25: incidente | B25: 20 | C25: recibido_en | D25: TIMESTAMPTZ | H25: Sí | J25: Recepción de la notificación.
A26: incidente | B26: 21 | C26: es_irsp | D26: BOOLEAN | H26: Sí | J26: Determinación de Calidad.
A27: incidente | B27: 22 | C27: clasificacion_id | D27: INTEGER | F27: Sí | H27: Sí | I27: catalogo_item.id | J27: CLASIFICACION_IRSP: FCN, cuasifalla, adverso, centinela.
A28: incidente | B28: 23 | C28: grado_dano_id | D28: INTEGER | F28: Sí | H28: Sí | I28: catalogo_item.id | J28: GRADO_DANO: ninguno, leve, moderado, grave, muerte.
A29: incidente | B29: 24 | C29: evento_trascendente_id | D29: INTEGER | F29: Sí | H29: Sí | I29: catalogo_item.id | J29: EVENTO_TRASCENDENTE.
A30: incidente | B30: 25 | C30: observaciones_clasificacion | D30: TEXT | H30: Sí | J30: Observaciones del Servicio de Calidad.
A31: incidente | B31: 26 | C31: clasificado_por | D31: INTEGER | F31: Sí | H31: Sí | I31: usuario.id | J31: Usuario que clasifica.
A32: incidente | B32: 27 | C32: clasificado_en | D32: TIMESTAMPTZ | H32: Sí | J32: Fecha de clasificación.
A33: incidente | B33: 28 | C33: capturado_dgces | D33: BOOLEAN | H33: No | J33: Capturado en la plataforma federal SREA.
A34: incidente | B34: 29 | C34: folio_dgces | D34: VARCHAR(30) | H34: Sí | J34: Folio asignado por la plataforma federal.
A35: incidente | B35: 30 | C35: capturado_dgces_en | D35: DATE | H35: Sí | J35: Fecha de captura federal.
A36: incidente | B36: 31 | C36: created_at | D36: TIMESTAMPTZ | H36: No | J36: Fecha de creación (Sequelize).
A37: incidente | B37: 32 | C37: updated_at | D37: TIMESTAMPTZ | H37: No | J37: Fecha de última modificación (Sequelize).
A39: incidente_tipo | Tipo y subtipo de incidente (RF-010); orden 1 y 2 como en la base IRSP.
A40: incidente_tipo | B40: 1 | C40: incidente_id | D40: INTEGER | E40: Sí | F40: Sí | H40: No | I40: incidente.id | J40: Incidente.
A41: incidente_tipo | B41: 2 | C41: tipo_item_id | D41: INTEGER | E41: Sí | F41: Sí | H41: No | I41: catalogo_item.id | J41: Subtipo de TIPO_INCIDENTE (padre = tipo).
A42: incidente_tipo | B42: 3 | C42: orden | D42: SMALLINT | H42: No | J42: Prioridad del tipo.
...

Sheet SUG
A1: Diccionario de datos | SUG: Quejas, sugerencias y felicitaciones
A2: P.I.C. TT2 2026-B060 | PostgreSQL 14+ | Fuente: modelo_er_tt2.drawio
A4: Tabla | B4: # | C4: Columna | D4: Tipo PostgreSQL | E4: PK | F4: FK | G4: Único | H4: Nulo | I4: Referencia | J4: Descripción
A5: qsf | Queja, sugerencia, reclamo o felicitación (CU-06, CU-15, CU-16).
A6: qsf | B6: 1 | C6: id | D6: INTEGER | E6: Sí | H6: No | J6: Identificador.
A7: qsf | B7: 2 | C7: folio | D7: VARCHAR(20) | G7: Sí | H7: No | J7: SUG-AAAA-NNNN.
A8: qsf | B8: 3 | C8: tipo | D8: VARCHAR(12) | H8: No | J8: QUEJA, SUGERENCIA, RECLAMO, FELICITACION.
A9: qsf | B9: 4 | C9: medio_captacion_id | D9: INTEGER | F9: Sí | H9: No | I9: catalogo_item.id | J9: BUZON, EGRESO, PRESENCIAL, KIOSCO, SESTAD.
A10: qsf | B10: 5 | C10: origen | D10: VARCHAR(10) | H10: No | J10: DIRECTA, ENCUESTA.
A11: qsf | B11: 6 | C11: encuesta_id | D11: BIGINT | F11: Sí | H11: Sí | I11: encuesta.id | J11: Encuesta de origen (RF-032, CU-17 A2).
A12: qsf | B12: 7 | C12: fecha_manifestacion | D12: DATE | H12: Sí | J12: Fecha anotada por el usuario.
A13: qsf | B13: 8 | C13: hora | D13: TIME | H13: Sí | J13: Hora de la manifestación.
A14: qsf | B14: 9 | C14: fecha_recepcion | D14: DATE | H14: No | J14: Fecha de recepción en Calidad.
A15: qsf | B15: 10 | C15: servicio_id | D15: INTEGER | F15: Sí | H15: Sí | I15: servicio.id | J15: Servicio señalado por el usuario.
A16: qsf | B16: 11 | C16: nombre_manifestante | D16: VARCHAR(160) | H16: Sí | J16: Nulo si es anónima.
A17: qsf | B17: 12 | C17: numero_registro | D17: VARCHAR(20) | H17: Sí | J17: Registro del paciente (sin validar).
A18: qsf | B18: 13 | C18: domicilio | D18: VARCHAR(255) | H18: Sí | J18: Contacto (CU-06 A1).
A19: qsf | B19: 14 | C19: telefono | D19: VARCHAR(20) | H19: Sí | J19: Contacto (CU-06 A1).
A20: qsf | B20: 15 | C20: anonimo | D20: BOOLEAN | H20: No | J20: Solo sugerencias y felicitaciones (CU-06 A3).
A21: qsf | B21: 16 | C21: descripcion | D21: TEXT | H21: No | J21: Manifestación del usuario.
A22: qsf | B22: 17 | C22: solicita_respuesta | D22: BOOLEAN | H22: No | J22: CU-16 A3.
A23: qsf | B23: 18 | C23: aviso_privacidad_aceptado | D23: BOOLEAN | H23: No | J23: RNF-006.
A24: qsf | B24: 19 | C24: capturado_por | D24: INTEGER | F24: Sí | H24: Sí | I24: usuario.id | J24: Nulo si proviene del kiosco.
A25: qsf | B25: 20 | C25: estatus | D25: VARCHAR(25) | H25: No | J25: PENDIENTE_CLASIFICACION, REQUIERE_INFORMACION, CLASIFICADA, EN_SEGUIMIENTO, RESUELTA, ARCHIVADA.
A26: qsf | B26: 21 | C26: servicio_clasif_id | D26: INTEGER | F26: Sí | H26: Sí | I26: servicio.id | J26: Servicio involucrado según Calidad.
A27: qsf | B27: 22 | C27: dimension_id | D27: INTEGER | F27: Sí | H27: Sí | I27: catalogo_item.id | J27: DIMENSION_CALIDAD (pendiente del hospital).
A28: qsf | B28: 23 | C28: clasificacion_id | D28: INTEGER | F28: Sí | H28: Sí | I28: catalogo_item.id | J28: CLASIFICACION_QSF (pendiente del hospital).
A29: qsf | B29: 24 | C29: clasificado_por | D29: INTEGER | F29: Sí | H29: Sí | I29: usuario.id | J29: Usuario que clasifica.
A30: qsf | B30: 25 | C30: clasificado_en | D30: TIMESTAMPTZ | H30: Sí | J30: Fecha de clasificación.
A31: qsf | B31: 26 | C31: resolucion | D31: TEXT | H31: Sí | J31: Resolución registrada.
A32: qsf | B32: 27 | C32: resuelto_en | D32: TIMESTAMPTZ | H32: Sí | J32: Fecha de cierre.
A33: qsf | B33: 28 | C33: capturado_dgces | D33: BOOLEAN | H33: No | J33: Capturado en la plataforma federal SUG.
A34: qsf | B34: 29 | C34: folio_dgces | D34: VARCHAR(30) | H34: Sí | J34: Folio federal.
A35: qsf | B35: 30 | C35: capturado_dgces_en | D35: DATE | H35: Sí | J35: Fecha de captura federal.
A36: qsf | B36: 31 | C36: created_at | D36: TIMESTAMPTZ | H36: No | J36: Fecha de creación (Sequelize).
A37: qsf | B37: 32 | C37: updated_at | D37: TIMESTAMPTZ | H37: No | J37: Fecha de última modificación (Sequelize).
A39: qsf_seguimiento | Historial de seguimiento de la QSF (CU-16).
A40: qsf_seguimiento | B40: 1 | C40: id | D40: INTEGER | E40: Sí | H40: No | J40: Identificador.
A41: qsf_seguimiento | B41: 2 | C41: qsf_id | D41: INTEGER | F41: Sí | H41: No | I41: qsf.id | J41: QSF.
A42: qsf_seguimiento | B42: 3 | C42: tipo | D42: VARCHAR(20) | H42: No | J42: OFICIO_ENVIADO, RESPUESTA_RECIBIDA, NOTA, CIERRE.
...

Sheet Motor_encuestas
A1: Diccionario de datos | Motor de encuestas (SUG y SESTAD)
A2: P.I.C. TT2 2026-B060 | PostgreSQL 14+ | Fuente: modelo_er_tt2.drawio
A4: Tabla | B4: # | C4: Columna | D4: Tipo PostgreSQL | E4: PK | F4: FK | G4: Único | H4: Nulo | I4: Referencia | J4: Descripción
A5: instrumento | Formato de encuesta versionado (egreso, SESTAD CE, HOSP, URG).
A6: instrumento | B6: 1 | C6: id | D6: INTEGER | E6: Sí | H6: No | J6: Identificador.
A7: instrumento | B7: 2 | C7: clave | D7: VARCHAR(30) | G7: Comp. | H7: No | J7: Ej. EGRESO, SESTAD_CE, SESTAD_HOSP, SESTAD_URG.
A8: instrumento | B8: 3 | C8: version | D8: SMALLINT | G8: Comp. | H8: No | J8: Versión del formato.
A9: instrumento | B9: 4 | C9: nombre | D9: VARCHAR(160) | H9: No | J9: Nombre del instrumento.
A10: instrumento | B10: 5 | C10: codigo_formato | D10: VARCHAR(30) | H10: Sí | J10: Ej. MP-1021-214-04, MP-1021-107-01.
A11: instrumento | B11: 6 | C11: modulo | D11: VARCHAR(10) | H11: No | J11: SUG, SESTAD.
A12: instrumento | B12: 7 | C12: vigente | D12: BOOLEAN | H12: No | J12: Versión en uso.
A13: instrumento | B13: 8 | C13: created_at | D13: TIMESTAMPTZ | H13: No | J13: Fecha de creación (Sequelize).
A14: instrumento | B14: 9 | C14: updated_at | D14: TIMESTAMPTZ | H14: No | J14: Fecha de última modificación (Sequelize).
A16: instrumento_seccion | Secciones del instrumento.
A17: instrumento_seccion | B17: 1 | C17: id | D17: INTEGER | E17: Sí | H17: No | J17: Identificador.
A18: instrumento_seccion | B18: 2 | C18: instrumento_id | D18: INTEGER | F18: Sí | H18: No | I18: instrumento.id | J18: Instrumento.
A19: instrumento_seccion | B19: 3 | C19: clave | D19: VARCHAR(5) | H19: Sí | J19: Ej. A, B, C.
A20: instrumento_seccion | B20: 4 | C20: titulo | D20: VARCHAR(255) | H20: No | J20: Título de la sección.
A21: instrumento_seccion | B21: 5 | C21: orden | D21: SMALLINT | H21: No | J21: Orden.
A22: instrumento_seccion | B22: 6 | C22: created_at | D22: TIMESTAMPTZ | H22: No | J22: Fecha de creación (Sequelize).
A23: instrumento_seccion | B23: 7 | C23: updated_at | D23: TIMESTAMPTZ | H23: No | J23: Fecha de última modificación (Sequelize).
A25: pregunta | Reactivos con lógica de salto.
A26: pregunta | B26: 1 | C26: id | D26: INTEGER | E26: Sí | H26: No | J26: Identificador.
A27: pregunta | B27: 2 | C27: seccion_id | D27: INTEGER | F27: Sí | H27: No | I27: instrumento_seccion.id | J27: Sección.
A28: pregunta | B28: 3 | C28: numero | D28: VARCHAR(10) | H28: No | J28: Número impreso en el formato.
A29: pregunta | B29: 4 | C29: texto | D29: TEXT | H29: No | J29: Enunciado.
A30: pregunta | B30: 5 | C30: tipo_respuesta | D30: VARCHAR(10) | H30: No | J30: UNICA, MULTIPLE, TEXTO, NUMERO.
A31: pregunta | B31: 6 | C31: obligatoria | D31: BOOLEAN | H31: No | J31: Si exige respuesta.
A32: pregunta | B32: 7 | C32: orden | D32: SMALLINT | H32: No | J32: Orden.
A33: pregunta | B33: 8 | C33: condicion_pregunta_id | D33: INTEGER | F33: Sí | H33: Sí | I33: pregunta.id | J33: Se muestra solo si esta pregunta...
A34: pregunta | B34: 9 | C34: condicion_opcion_id | D34: INTEGER | F34: Sí | H34: Sí | I34: opcion_respuesta.id | J34: ...tiene esta opción seleccionada.
A35: pregunta | B35: 10 | C35: created_at | D35: TIMESTAMPTZ | H35: No | J35: Fecha de creación (Sequelize).
A36: pregunta | B36: 11 | C36: updated_at | D36: TIMESTAMPTZ | H36: No | J36: Fecha de última modificación (Sequelize).
A38: opcion_respuesta | Opciones de respuesta por pregunta.
A39: opcion_respuesta | B39: 1 | C39: id | D39: INTEGER | E39: Sí | H39: No | J39: Identificador.
A40: opcion_respuesta | B40: 2 | C40: pregunta_id | D40: INTEGER | F40: Sí | H40: No | I40: pregunta.id | J40: Pregunta.
A41: opcion_respuesta | B41: 3 | C41: clave | D41: VARCHAR(10) | H41: No | J41: Ej. a, b, SI, NO, NR.
A42: opcion_respuesta | B42: 4 | C42: texto | D42: VARCHAR(255) | H42: No | J42: Texto visible.
A43: opcion_respuesta | B43: 5 | C43: valor | D43: NUMERIC(5,2) | H43: Sí | J43: Valor numérico para cálculos.
A44: opcion_respuesta | B44: 6 | C44: es_favorable | D44: BOOLEAN | H44: Sí | J44: Cuenta como respuesta positiva en indicadores.
...

Sheet SESTAD
A1: Diccionario de datos | SESTAD: Encuestas de satisfacción
A2: P.I.C. TT2 2026-B060 | PostgreSQL 14+ | Fuente: modelo_er_tt2.drawio
A4: Tabla | B4: # | C4: Columna | D4: Tipo PostgreSQL | E4: PK | F4: FK | G4: Único | H4: Nulo | I4: Referencia | J4: Descripción
A5: encuesta_sestad | Datos propios de la encuesta SESTAD (RF-028).
A6: encuesta_sestad | B6: 1 | C6: encuesta_id | D6: BIGINT | E6: Sí | F6: Sí | H6: No | I6: encuesta.id | J6: Encuesta (1:1).
A7: encuesta_sestad | B7: 2 | C7: periodo_id | D7: INTEGER | F7: Sí | H7: No | I7: periodo.id | J7: Cuatrimestre.
A8: encuesta_sestad | B8: 3 | C8: area | D8: VARCHAR(4) | H8: No | J8: CE, HOSP, URG.
A9: encuesta_sestad | B9: 4 | C9: servicio_id | D9: INTEGER | F9: Sí | H9: Sí | I9: servicio.id | J9: Especialidad o servicio.
A10: encuesta_sestad | B10: 5 | C10: numero_registro | D10: VARCHAR(20) | H10: Sí | J10: Registro del paciente.
A12: periodo | Periodos cuatrimestrales; reutilizable por MECIC e INDICAS.
A13: periodo | B13: 1 | C13: id | D13: INTEGER | E13: Sí | H13: No | J13: Identificador.
A14: periodo | B14: 2 | C14: modulo | D14: VARCHAR(10) | G14: Comp. | H14: No | J14: SESTAD (MECIC, INDICAS a futuro).
A15: periodo | B15: 3 | C15: anio | D15: SMALLINT | G15: Comp. | H15: No | J15: Año.
A16: periodo | B16: 4 | C16: cuatrimestre | D16: SMALLINT | G16: Comp. | H16: No | J16: 1 a 3.
A17: periodo | B17: 5 | C17: fecha_inicio | D17: DATE | H17: No | J17: Inicio.
A18: periodo | B18: 6 | C18: fecha_fin | D18: DATE | H18: No | J18: Fin.
A19: periodo | B19: 7 | C19: estatus | D19: VARCHAR(8) | H19: No | J19: ABIERTO, CERRADO.
A20: periodo | B20: 8 | C20: created_at | D20: TIMESTAMPTZ | H20: No | J20: Fecha de creación (Sequelize).
A21: periodo | B21: 9 | C21: updated_at | D21: TIMESTAMPTZ | H21: No | J21: Fecha de última modificación (Sequelize).
A23: periodo_variable | Variables institucionales del periodo (RF-029).
A24: periodo_variable | B24: 1 | C24: periodo_id | D24: INTEGER | E24: Sí | F24: Sí | H24: No | I24: periodo.id | J24: Periodo.
A25: periodo_variable | B25: 2 | C25: clave | D25: VARCHAR(30) | E25: Sí | H25: No | J25: EGRESOS_HOSP, CONSULTAS_EXT, ALTAS_URG.
A26: periodo_variable | B26: 3 | C26: valor | D26: INTEGER | H26: No | J26: Valor reportado.
A27: periodo_variable | B27: 4 | C27: created_at | D27: TIMESTAMPTZ | H27: No | J27: Fecha de creación (Sequelize).
A28: periodo_variable | B28: 5 | C28: updated_at | D28: TIMESTAMPTZ | H28: No | J28: Fecha de última modificación (Sequelize).
A30: concentrado | Instantánea del concentrado al cierre del periodo (RF-030).
A31: concentrado | B31: 1 | C31: id | D31: INTEGER | E31: Sí | H31: No | J31: Identificador.
A32: concentrado | B32: 2 | C32: periodo_id | D32: INTEGER | F32: Sí | H32: No | I32: periodo.id | J32: Periodo.
A33: concentrado | B33: 3 | C33: instrumento_id | D33: INTEGER | F33: Sí | H33: No | I33: instrumento.id | J33: Instrumento concentrado.
A34: concentrado | B34: 4 | C34: datos | D34: JSONB | H34: No | J34: Conteos por pregunta y opción.
A35: concentrado | B35: 5 | C35: generado_por | D35: INTEGER | F35: Sí | H35: No | I35: usuario.id | J35: Usuario que cierra.
A36: concentrado | B36: 6 | C36: generado_en | D36: TIMESTAMPTZ | H36: No | J36: Fecha de generación.

Sheet Relaciones
A1: Llaves foráneas del modelo
A3: Tabla hija | B3: Columna | C3: Tabla padre | D3: Columna padre | E3: Nulo | F3: Cardinalidad | G3: Dibujada en el diagrama
A4: rol_permiso | B4: rol_id | C4: rol | D4: id | E4: No | F4: N : 1 | G4: Sí
A5: rol_permiso | B5: permiso_id | C5: permiso | D5: id | E5: No | F5: N : 1 | G5: Sí
A6: usuario | B6: rol_id | C6: rol | D6: id | E6: No | F6: N : 1 | G6: Sí
A7: usuario | B7: servicio_id | C7: servicio | D7: id | E7: Sí | F7: N : 0..1 | G7: No (solo atributo)
A8: catalogo_item | B8: catalogo_id | C8: catalogo | D8: id | E8: No | F8: N : 1 | G8: Sí
A9: catalogo_item | B9: padre_id | C9: catalogo_item | D9: id | E9: Sí | F9: N : 0..1 | G9: No (solo atributo)
A10: paciente | B10: genero_id | C10: catalogo_item | D10: id | E10: Sí | F10: N : 0..1 | G10: No (solo atributo)
A11: bitacora | B11: usuario_id | C11: usuario | D11: id | E11: Sí | F11: N : 0..1 | G11: No (solo atributo)
A12: notificacion | B12: usuario_id | C12: usuario | D12: id | E12: No | F12: N : 1 | G12: No (solo atributo)
A13: archivo_adjunto | B13: subido_por | C13: usuario | D13: id | E13: Sí | F13: N : 0..1 | G13: No (solo atributo)
A14: borrador | B14: usuario_id | C14: usuario | D14: id | E14: No | F14: N : 1 | G14: No (solo atributo)
... A89: encuesta_egreso | B89: diagnostico_id | C89: diagnostico | D89: id | E89: Sí | F89: N : 0..1 | G89: No (solo atributo)
